Workbook
Name apellidos: Hoja6!$D$6:$D$25
Name Camioneros: Tabla1[#All]
Name Camiones: Tabla2[#All]
Name Direccion: Tabla9[#All]
Name Distribuciones: Tabla3[#All]
Name nombres: Hoja6!$C$6:$C$45
Name Paquetes: Tabla4[#All]
Name Provincias: Tabla5[#All]
Name Tipo: Tabla10[#All]

Sheet Camioneros
B4: dni | C4: nombre | D4: apellido | E4: telefono | F4: direccion | G4: salario | H4: camión asignado
B5: 12345678A | C5: {=INDEX(Hoja6!$H$6:$H$15,ROUND(RAND()*9,0)+1)} -> Ethan | D5: {=INDEX(Hoja6!$I$6:$I$15,ROUND(RAND()*9,0)+1)} -> Davis | E5: 555-123-4567 | F5: {=INDEX(Tabla9[id_direccion],ROUND(RAND()*215,0)+1)} -> E-LED | G5: =RANDBETWEEN(2000,5000) -> 3975 | H5: 1234AAA
B6: 23456789B | C6: {=INDEX(Hoja6!$H$6:$H$15,ROUND(RAND()*9,0)+1)} -> Emma | D6: {=INDEX(Hoja6!$I$6:$I$15,ROUND(RAND()*9,0)+1)} -> Davis | E6: 555-234-5678 | F6: {=INDEX(Tabla9[id_direccion],ROUND(RAND()*215,0)+1)} -> O-LLE | G6: =RANDBETWEEN(2000,5000) -> 2150 | H6: 2345BBB
B7: 12345678A | C7: {=INDEX(Hoja6!$H$6:$H$15,ROUND(RAND()*9,0)+1)} -> Emma | D7: {=INDEX(Hoja6!$I$6:$I$15,ROUND(RAND()*9,0)+1)} -> Taylor | E7: 555-345-6789 | F7: {=INDEX(Tabla9[id_direccion],ROUND(RAND()*215,0)+1)} -> G-NID | G7: =RANDBETWEEN(2000,5000) -> 2785 | H7: 3456CCC
B8: 54321098B | C8: {=INDEX(Hoja6!$H$6:$H$15,ROUND(RAND()*9,0)+1)} -> Emma | D8: {=INDEX(Hoja6!$I$6:$I$15,ROUND(RAND()*9,0)+1)} -> Jackson | E8: 555-456-7890 | F8: {=INDEX(Tabla9[id_direccion],ROUND(RAND()*215,0)+1)} -> A-EDE | G8: =RANDBETWEEN(2000,5000) -> 4487 | H8: 4567DDD
B9: 98765432C | C9: {=INDEX(Hoja6!$H$6:$H$15,ROUND(RAND()*9,0)+1)} -> Ethan | D9: {=INDEX(Hoja6!$I$6:$I$15,ROUND(RAND()*9,0)+1)} -> Taylor | E9: 555-567-8901 | F9: {=INDEX(Tabla9[id_direccion],ROUND(RAND()*215,0)+1)} -> S-ALL | G9: =RANDBETWEEN(2000,5000) -> 3890 | H9: 5678EEE
B10: 45678901D | C10: {=INDEX(Hoja6!$H$6:$H$15,ROUND(RAND()*9,0)+1)} -> Emma | D10: {=INDEX(Hoja6!$I$6:$I$15,ROUND(RAND()*9,0)+1)} -> Davis | E10: 555-678-9012 | F10: {=INDEX(Tabla9[id_direccion],ROUND(RAND()*215,0)+1)} -> E-IDA | G10: =RANDBETWEEN(2000,5000) -> 3329 | H10: 6789FFF
B11: 23456789E | C11: {=INDEX(Hoja6!$H$6:$H$15,ROUND(RAND()*9,0)+1)} -> Emily | D11: {=INDEX(Hoja6!$I$6:$I$15,ROUND(RAND()*9,0)+1)} -> Davis | E11: 555-789-0123 | F11: {=INDEX(Tabla9[id_direccion],ROUND(RAND()*215,0)+1)} -> L-RDÓ | G11: =RANDBETWEEN(2000,5000) -> 3308 | H11: 7890GGG
B12: 89012345F | C12: {=INDEX(Hoja6!$H$6:$H$15,ROUND(RAND()*9,0)+1)} -> Sophia | D12: {=INDEX(Hoja6!$I$6:$I$15,ROUND(RAND()*9,0)+1)} -> Wilson | E12: 555-890-1234 | F12: {=INDEX(Tabla9[id_direccion],ROUND(RAND()*215,0)+1)} -> I-UEÑ | G12: =RANDBETWEEN(2000,5000) -> 2336 | H12: 8901HHH
B13: 67890123G | C13: {=INDEX(Hoja6!$H$6:$H$15,ROUND(RAND()*9,0)+1)} -> Olivia | D13: {=INDEX(Hoja6!$I$6:$I$15,ROUND(RAND()*9,0)+1)} -> Moore | E13: 555-901-2345 | F13: {=INDEX(Tabla9[id_direccion],ROUND(RAND()*215,0)+1)} -> O-UE1 | G13: =RANDBETWEEN(2000,5000) -> 3659 | H13: 9012III
B14: 34567890H | C14: {=INDEX(Hoja6!$H$6:$H$15,ROUND(RAND()*9,0)+1)} -> William | D14: {=INDEX(Hoja6!$I$6:$I$15,ROUND(RAND()*9,0)+1)} -> Johnson | E14: 555-012-3456 | F14: {=INDEX(Tabla9[id_direccion],ROUND(RAND()*215,0)+1)} -> U-NID | G14: =RANDBETWEEN(2000,5000) -> 4538 | H14: 0123JJJ
B15: 01234567J | C15: {=INDEX(Hoja6!$H$6:$H$15,ROUND(RAND()*9,0)+1)} -> Emma | D15: {=INDEX(Hoja6!$I$6:$I$15,ROUND(RAND()*9,0)+1)} -> Anderson | E15: 555-123-4567 | F15: {=INDEX(Tabla9[id_direccion],ROUND(RAND()*215,0)+1)} -> R-ADE | G15: =RANDBETWEEN(2000,5000) -> 4334 | H15: 1234KKK
B16: 89012345K | C16: {=INDEX(Hoja6!$H$6:$H$15,ROUND(RAND()*9,0)+1)} -> Charlotte | D16: {=INDEX(Hoja6!$I$6:$I$15,ROUND(RAND()*9,0)+1)} -> Taylor | E16: 555-234-5678 | F16: {=INDEX(Tabla9[id_direccion],ROUND(RAND()*215,0)+1)} -> L-OR2 | G16: =RANDBETWEEN(2000,5000) -> 2560 | H16: 2345LLL
... B34: 78901234D1 | C34: {=INDEX(Hoja6!$H$6:$H$15,ROUND(RAND()*9,0)+1)} -> Ethan | D34: {=INDEX(Hoja6!$I$6:$I$15,ROUND(RAND()*9,0)+1)} -> Taylor | E34: 555-012-3456 | F34: {=INDEX(Tabla9[id_direccion],ROUND(RAND()*215,0)+1)} -> U-MAY | G34: =RANDBETWEEN(2000,5000) -> 4271 | H34: 0123DDD
B35: 567890120 | C35: {=INDEX(Hoja6!$H$6:$H$15,ROUND(RAND()*9,0)+1)} -> Ethan | D35: {=INDEX(Hoja6!$I$6:$I$15,ROUND(RAND()*9,0)+1)} -> Moore | E35: 555-123-4567 | F35: {=INDEX(Tabla9[id_direccion],ROUND(RAND()*215,0)+1)} -> I-RDÓ | G35: =RANDBETWEEN(2000,5000) -> 2718 | H35: 1234EEE
B36: 34567890F1 | C36: {=INDEX(Hoja6!$H$6:$H$15,ROUND(RAND()*9,0)+1)} -> William | D36: {=INDEX(Hoja6!$I$6:$I$15,ROUND(RAND()*9,0)+1)} -> Johnson | E36: 555-234-5678 | F36: {=INDEX(Tabla9[id_direccion],ROUND(RAND()*215,0)+1)} -> T-ADE | G36: =RANDBETWEEN(2000,5000) -> 2725 | H36: 2345FFF
B37: 12345678G1 | C37: {=INDEX(Hoja6!$H$6:$H$15,ROUND(RAND()*9,0)+1)} -> Ethan | D37: {=INDEX(Hoja6!$I$6:$I$15,ROUND(RAND()*9,0)+1)} -> Johnson | E37: 555-345-6789 | F37: {=INDEX(Tabla9[id_direccion],ROUND(RAND()*215,0)+1)} -> S-IDA | G37: =RANDBETWEEN(2000,5000) -> 2359 | H37: 3456GGG
B38: 90123456H1 | C38: {=INDEX(Hoja6!$H$6:$H$15,ROUND(RAND()*9,0)+1)} -> James | D38: {=INDEX(Hoja6!$I$6:$I$15,ROUND(RAND()*9,0)+1)} -> Wilson | E38: 555-456-7890 | F38: {=INDEX(Tabla9[id_direccion],ROUND(RAND()*215,0)+1)} -> M-ÑA2 | G38: =RANDBETWEEN(2000,5000) -> 4634 | H38: 4567HHH
B39: 78901234J1 | C39: {=INDEX(Hoja6!$H$6:$H$15,ROUND(RAND()*9,0)+1)} -> Alexander | D39: {=INDEX(Hoja6!$I$6:$I$15,ROUND(RAND()*9,0)+1)} -> Taylor | E39: 555-567-8901 | F39: {=INDEX(Tabla9[id_direccion],ROUND(RAND()*215,0)+1)} -> A-ADE | G39: =RANDBETWEEN(2000,5000) -> 2090 | H39: 5678III
B40: 56789012K1 | C40: {=INDEX(Hoja6!$H$6:$H$15,ROUND(RAND()*9,0)+1)} -> Olivia | D40: {=INDEX(Hoja6!$I$6:$I$15,ROUND(RAND()*9,0)+1)} -> Taylor | E40: 555-678-9012 | F40: {=INDEX(Tabla9[id_direccion],ROUND(RAND()*215,0)+1)} -> C-ELA | G40: =RANDBETWEEN(2000,5000) -> 2960 | H40: 6789JJJ
B41: 34567890L1 | C41: {=INDEX(Hoja6!$H$6:$H$15,ROUND(RAND()*9,0)+1)} -> Alexander | D41: {=INDEX(Hoja6!$I$6:$I$15,ROUND(RAND()*9,0)+1)} -> Anderson | E41: 555-789-0123 | F41: {=INDEX(Tabla9[id_direccion],ROUND(RAND()*215,0)+1)} -> G-ÑO1 | G41: =RANDBETWEEN(2000,5000) -> 2030 | H41: 7890KKK
B42: 12345678M1 | C42: {=INDEX(Hoja6!$H$6:$H$15,ROUND(RAND()*9,0)+1)} -> Emily | D42: {=INDEX(Hoja6!$I$6:$I$15,ROUND(RAND()*9,0)+1)} -> Johnson | E42: 555-890-1234 | F42: {=INDEX(Tabla9[id_direccion],ROUND(RAND()*215,0)+1)} -> O-UE1 | G42: =RANDBETWEEN(2000,5000) -> 2298 | H42: 8901LLL
B43: 90123456N1 | C43: {=INDEX(Hoja6!$H$6:$H$15,ROUND(RAND()*9,0)+1)} -> Ethan | D43: {=INDEX(Hoja6!$I$6:$I$15,ROUND(RAND()*9,0)+1)} -> Moore | E43: 555-901-2345 | F43: {=INDEX(Tabla9[id_direccion],ROUND(RAND()*215,0)+1)} -> U-ADE | G43: =RANDBETWEEN(2000,5000) -> 2185 | H43: 9012MMM
B44: 78901234P1 | C44: {=INDEX(Hoja6!$H$6:$H$15,ROUND(RAND()*9,0)+1)} -> James | D44: {=INDEX(Hoja6!$I$6:$I$15,ROUND(RAND()*9,0)+1)} -> Taylor | E44: 555-012-3456 | F44: {=INDEX(Tabla9[id_direccion],ROUND(RAND()*215,0)+1)} -> L-LCO | G44: =RANDBETWEEN(2000,5000) -> 4652 | H44: 0123NNN
B45: 56789012Q1 | C45: {=INDEX(Hoja6!$H$6:$H$15,ROUND(RAND()*9,0)+1)} -> Olivia | D45: {=INDEX(Hoja6!$I$6:$I$15,ROUND(RAND()*9,0)+1)} -> Smith | E45: 555-123-4567 | F45: {=INDEX(Tabla9[id_direccion],ROUND(RAND()*215,0)+1)} -> E-LED | G45: =RANDBETWEEN(2000,5000) -> 3541 | H45: 1234OOO
B46: 34567890R1 | C46: {=INDEX(Hoja6!$H$6:$H$15,ROUND(RAND()*9,0)+1)} -> Ethan | D46: {=INDEX(Hoja6!$I$6:$I$15,ROUND(RAND()*9,0)+1)} -> Wilson | E46: 555-234-5678 | F46: {=INDEX(Tabla9[id_direccion],ROUND(RAND()*215,0)+1)} -> A-VEN | G46: =RANDBETWEEN(2000,5000) -> 2954 | H46: 2345PPP
B47: 12345678S1 | C47: {=INDEX(Hoja6!$H$6:$H$15,ROUND(RAND()*9,0)+1)} -> Benjamin | D47: {=INDEX(Hoja6!$I$6:$I$15,ROUND(RAND()*9,0)+1)} -> Jackson | E47: 555-345-6789 | F47: {=INDEX(Tabla9[id_direccion],ROUND(RAND()*215,0)+1)} -> D-NTO | G47: =RANDBETWEEN(2000,5000) -> 4376 | H47: 3456QQQ

Sheet Camiones
B3: matricula | C3: modelo | D3: tipo
B4: 1234AAA | C4: Volvo FH | D4: {=INDEX(Tabla10[id_tipo],ROUND(RAND()*9,0)+1)} -> FOR
B5: 2345BBB | C5: Scania R | D5: {=INDEX(Tabla10[id_tipo],ROUND(RAND()*9,0)+1)} -> GRÚ
B6: 3456CCC | C6: Foton BJ3042V8JEA-A | D6: {=INDEX(Tabla10[id_tipo],ROUND(RAND()*9,0)+1)} -> UET
B7: 4567DDD | C7: Volvo FL7 | D7: {=INDEX(Tabla10[id_tipo],ROUND(RAND()*9,0)+1)} -> UET
B8: 5678EEE | C8: Dongfeng KC | D8: {=INDEX(Tabla10[id_tipo],ROUND(RAND()*9,0)+1)} -> REF
B9: 6789FFF | C9: Scania R620 | D9: {=INDEX(Tabla10[id_tipo],ROUND(RAND()*9,0)+1)} -> CIS
B10: 7890GGG | C10: Isuzu NPR | D10: {=INDEX(Tabla10[id_tipo],ROUND(RAND()*9,0)+1)} -> TRÁ
B11: 8901HHH | C11: Hino 500 | D11: {=INDEX(Tabla10[id_tipo],ROUND(RAND()*9,0)+1)} -> UET
B12: 9012III | C12: Mercedes-Benz Actros | D12: {=INDEX(Tabla10[id_tipo],ROUND(RAND()*9,0)+1)} -> REF
B13: 0123JJJ | C13: Iveco Stralis | D13: {=INDEX(Tabla10[id_tipo],ROUND(RAND()*9,0)+1)} -> UET
B14: 1234KKK | C14: Kenworth T680 | D14: {=INDEX(Tabla10[id_tipo],ROUND(RAND()*9,0)+1)} -> URG
B15: 2345LLL | C15: MAN TGS | D15: {=INDEX(Tabla10[id_tipo],ROUND(RAND()*9,0)+1)} -> PAR
... B46: 3456QQQ | C46: Renault C | D46: {=INDEX(Tabla10[id_tipo],ROUND(RAND()*9,0)+1)} -> CIS

Sheet Tipo
C3: Tipo | D3: potencia | E3: id_tipo
C4: Furgón | D4: 300 CV | E4: =UPPER(SUBSTITUTE(MID(C4,RANDBETWEEN(1,LEN(C4)-2),3)," ","")) -> URG
C5: Cisterna | D5: 350 CV | E5: =UPPER(SUBSTITUTE(MID(C5,RANDBETWEEN(1,LEN(C5)-2),3)," ","")) -> CIS
C6: Refrigerado | D6: 400 CV | E6: =UPPER(SUBSTITUTE(MID(C6,RANDBETWEEN(1,LEN(C6)-2),3)," ","")) -> REF
C7: Plataforma | D7: 450 CV | E7: =UPPER(SUBSTITUTE(MID(C7,RANDBETWEEN(1,LEN(C7)-2),3)," ","")) -> FOR
C8: Grúa | D8: 500 CV | E8: =UPPER(SUBSTITUTE(MID(C8,RANDBETWEEN(1,LEN(C8)-2),3)," ","")) -> GRÚ
C9: Volquete | D9: 550 CV | E9: =UPPER(SUBSTITUTE(MID(C9,RANDBETWEEN(1,LEN(C9)-2),3)," ","")) -> UET
C10: Reparto | D10: 600 CV | E10: =UPPER(SUBSTITUTE(MID(C10,RANDBETWEEN(1,LEN(C10)-2),3)," ","")) -> PAR
C11: Tráiler | D11: 650 CV | E11: =UPPER(SUBSTITUTE(MID(C11,RANDBETWEEN(1,LEN(C11)-2),3)," ","")) -> TRÁ
C12: Tanque | D12: 700 CV | E12: =UPPER(SUBSTITUTE(MID(C12,RANDBETWEEN(1,LEN(C12)-2),3)," ","")) -> ANQ
C13: Mudanza | D13: 750 CV | E13: =UPPER(SUBSTITUTE(MID(C13,RANDBETWEEN(1,LEN(C13)-2),3)," ","")) -> ANZ

Sheet Distribuciones
B5: camion | C5: paquete_codigo | D5: fecha
B6: {=INDEX(Tabla2[[#All],[matricula]],ROUND(RAND()*40,0)+1)} -> 8901BBB | C6: =Paquetes!B5 -> P-1 | D6: =RANDBETWEEN(DATE(2023,1,1),TODAY()) -> 45008
B7: {=INDEX(Tabla2[[#All],[matricula]],ROUND(RAND()*40,0)+1)} -> 9012III | C7: =Paquetes!B6 -> P-2 | D7: =RANDBETWEEN(DATE(2023,1,1),TODAY()) -> 44993
B8: {=INDEX(Tabla2[[#All],[matricula]],ROUND(RAND()*40,0)+1)} -> 3456CCC | C8: =Paquetes!B7 -> P-3 | D8: =RANDBETWEEN(DATE(2023,1,1),TODAY()) -> 44953
B9: {=INDEX(Tabla2[[#All],[matricula]],ROUND(RAND()*40,0)+1)} -> 5678EEE | C9: =Paquetes!B8 -> P-4 | D9: =RANDBETWEEN(DATE(2023,1,1),TODAY()) -> 44948
B10: {=INDEX(Tabla2[[#All],[matricula]],ROUND(RAND()*40,0)+1)} -> 9012MMM | C10: =Paquetes!B9 -> P-5 | D10: =RANDBETWEEN(DATE(2023,1,1),TODAY()) -> 45003
B11: {=INDEX(Tabla2[[#All],[matricula]],ROUND(RAND()*40,0)+1)} -> 5678YYY | C11: =Paquetes!B10 -> P-6 | D11: =RANDBETWEEN(DATE(2023,1,1),TODAY()) -> 44987
B12: {=INDEX(Tabla2[[#All],[matricula]],ROUND(RAND()*40,0)+1)} -> 5678III | C12: =Paquetes!B11 -> P-7 | D12: =RANDBETWEEN(DATE(2023,1,1),TODAY()) -> 44932
B13: {=INDEX(Tabla2[[#All],[matricula]],ROUND(RAND()*40,0)+1)} -> 3456WWW | C13: =Paquetes!B12 -> P-8 | D13: =RANDBETWEEN(DATE(2023,1,1),TODAY()) -> 44935
B14: {=INDEX(Tabla2[[#All],[matricula]],ROUND(RAND()*40,0)+1)} -> 9012CCC | C14: =Paquetes!B13 -> P-9 | D14: =RANDBETWEEN(DATE(2023,1,1),TODAY()) -> 44996
B15: {=INDEX(Tabla2[[#All],[matricula]],ROUND(RAND()*40,0)+1)} -> 9012SSS | C15: =Paquetes!B14 -> P-10 | D15: =RANDBETWEEN(DATE(2023,1,1),TODAY()) -> 44927
B16: {=INDEX(Tabla2[[#All],[matricula]],ROUND(RAND()*40,0)+1)} -> 5678III | C16: =Paquetes!B15 -> P-11 | D16: =RANDBETWEEN(DATE(2023,1,1),TODAY()) -> 45012
B17: {=INDEX(Tabla2[[#All],[matricula]],ROUND(RAND()*40,0)+1)} -> 8901BBB | C17: =Paquetes!B16 -> P-12 | D17: =RANDBETWEEN(DATE(2023,1,1),TODAY()) -> 44943
... B166: {=INDEX(Tabla2[[#All],[matricula]],ROUND(RAND()*40,0)+1)} -> 2345VVV | C166: =Paquetes!B165 -> P-161 | D166: =RANDBETWEEN(DATE(2023,1,1),TODAY()) -> 44974

Sheet Paquetes
B4: codigo | C4: descripcion | D4: destinatario
B5: =CONCATENATE("P","-",COUNTIF($D$5:D5,"*")) -> P-1 | C5: {=INDEX(Hoja6!L$6:L$98,ROUND(RAND()*92,0)+1)} -> Plancha | D5: {=INDEX(Tabla11[Dni],ROUND(RAND()*103,0)+1)} -> 34567890P
B6: =CONCATENATE("P","-",COUNTIF($D$5:D6,"*")) -> P-2 | C6: {=INDEX(Hoja6!L$6:L$98,ROUND(RAND()*92,0)+1)} -> Manta | D6: {=INDEX(Tabla11[Dni],ROUND(RAND()*103,0)+1)} -> 45678901C
B7: =CONCATENATE("P","-",COUNTIF($D$5:D7,"*")) -> P-3 | C7: {=INDEX(Hoja6!L$6:L$98,ROUND(RAND()*92,0)+1)} -> Planta | D7: {=INDEX(Tabla11[Dni],ROUND(RAND()*103,0)+1)} -> 45678901C
B8: =CONCATENATE("P","-",COUNTIF($D$5:D8,"*")) -> P-4 | C8: {=INDEX(Hoja6!L$6:L$98,ROUND(RAND()*92,0)+1)} -> Cargador | D8: {=INDEX(Tabla11[Dni],ROUND(RAND()*103,0)+1)} -> 90123456L
B9: =CONCATENATE("P","-",COUNTIF($D$5:D9,"*")) -> P-5 | C9: {=INDEX(Hoja6!L$6:L$98,ROUND(RAND()*92,0)+1)} -> Fiambrera | D9: {=INDEX(Tabla11[Dni],ROUND(RAND()*103,0)+1)} -> 12345678D
B10: =CONCATENATE("P","-",COUNTIF($D$5:D10,"*")) -> P-6 | C10: {=INDEX(Hoja6!L$6:L$98,ROUND(RAND()*92,0)+1)} -> Calcetines deportivos | D10: {=INDEX(Tabla11[Dni],ROUND(RAND()*103,0)+1)} -> 89012345H
B11: =CONCATENATE("P","-",COUNTIF($D$5:D11,"*")) -> P-7 | C11: {=INDEX(Hoja6!L$6:L$98,ROUND(RAND()*92,0)+1)} -> Papel higiénico | D11: {=INDEX(Tabla11[Dni],ROUND(RAND()*103,0)+1)} -> 23456789O
B12: =CONCATENATE("P","-",COUNTIF($D$5:D12,"*")) -> P-8 | C12: {=INDEX(Hoja6!L$6:L$98,ROUND(RAND()*92,0)+1)} -> Álbum de fotos | D12: {=INDEX(Tabla11[Dni],ROUND(RAND()*103,0)+1)} -> 23456789A
B13: =CONCATENATE("P","-",COUNTIF($D$5:D13,"*")) -> P-9 | C13: {=INDEX(Hoja6!L$6:L$98,ROUND(RAND()*92,0)+1)} -> Altavoz | D13: {=INDEX(Tabla11[Dni],ROUND(RAND()*103,0)+1)} -> 34567890C
B14: =CONCATENATE("P","-",COUNTIF($D$5:D14,"*")) -> P-10 | C14: {=INDEX(Hoja6!L$6:L$98,ROUND(RAND()*92,0)+1)} -> Cuaderno | D14: {=INDEX(Tabla11[Dni],ROUND(RAND()*103,0)+1)} -> 01234567M
B15: =CONCATENATE("P","-",COUNTIF($D$5:D15,"*")) -> P-11 | C15: {=INDEX(Hoja6!L$6:L$98,ROUND(RAND()*92,0)+1)} -> Planta de interior | D15: {=INDEX(Tabla11[Dni],ROUND(RAND()*103,0)+1)} -> 23456789Y
B16: =CONCATENATE("P","-",COUNTIF($D$5:D16,"*")) -> P-12 | C16: {=INDEX(Hoja6!L$6:L$98,ROUND(RAND()*92,0)+1)} -> Monitor | D16: {=INDEX(Tabla11[Dni],ROUND(RAND()*103,0)+1)} -> 34567890B
... B165: =CONCATENATE("P","-",COUNTIF($D$5:D165,"*")) -> P-161 | C165: {=INDEX(Hoja6!L$6:L$98,ROUND(RAND()*92,0)+1)} -> Auriculares | D165: {=INDEX(Tabla11[Dni],ROUND(RAND()*103,0)+1)} -> 67890123I

Sheet Destinatario
C5: Dni | D5: Nombre | E5: apellido | F5: dirección
C6: 12345678A | D6: {=INDEX(Hoja6!C$6:C$45,ROUND(RAND()*39,0)+1)} -> Francisco | E6: {=INDEX(Hoja6!D$6:D$45,ROUND(RAND()*39,0)+1)} -> Hernández | F6: {=INDEX(Tabla9[id_direccion],ROUND(RAND()*215,0)+1)} -> M-LIN
C7: 23456789B | D7: {=INDEX(Hoja6!C$6:C$45,ROUND(RAND()*39,0)+1)} -> Sergio | E7: {=INDEX(Hoja6!D$6:D$45,ROUND(RAND()*39,0)+1)} -> Navarro | F7: {=INDEX(Tabla9[id_direccion],ROUND(RAND()*215,0)+1)} -> R-ELA
C8: 34567890C | D8: {=INDEX(Hoja6!C$6:C$45,ROUND(RAND()*39,0)+1)} -> Raquel | E8: {=INDEX(Hoja6!D$6:D$45,ROUND(RAND()*39,0)+1)} -> Romero | F8: {=INDEX(Tabla9[id_direccion],ROUND(RAND()*215,0)+1)} -> E-ELA
C9: 45678901D | D9: {=INDEX(Hoja6!C$6:C$45,ROUND(RAND()*39,0)+1)} -> Raquel | E9: {=INDEX(Hoja6!D$6:D$45,ROUND(RAND()*39,0)+1)} -> Rodríguez | F9: {=INDEX(Tabla9[id_direccion],ROUND(RAND()*215,0)+1)} -> U-TIC
C10: 56789012E | D10: {=INDEX(Hoja6!C$6:C$45,ROUND(RAND()*39,0)+1)} -> Sofía | E10: {=INDEX(Hoja6!D$6:D$45,ROUND(RAND()*39,0)+1)} -> Gómez | F10: {=INDEX(Tabla9[id_direccion],ROUND(RAND()*215,0)+1)} -> A-ADE
C11: 67890123F | D11: {=INDEX(Hoja6!C$6:C$45,ROUND(RAND()*39,0)+1)} -> Laura | E11: {=INDEX(Hoja6!D$6:D$45,ROUND(RAND()*39,0)+1)} -> Martínez | F11: {=INDEX(Tabla9[id_direccion],ROUND(RAND()*215,0)+1)} -> I-DEL
C12: 78901234G | D12: {=INDEX(Hoja6!C$6:C$45,ROUND(RAND()*39,0)+1)} -> Paula | E12: {=INDEX(Hoja6!D$6:D$45,ROUND(RAND()*39,0)+1)} -> Ruiz | F12: {=INDEX(Tabla9[id_direccion],ROUND(RAND()*215,0)+1)} -> A-AVE
C13: 89012345H | D13: {=INDEX(Hoja6!C$6:C$45,ROUND(RAND()*39,0)+1)} -> Miguel | E13: {=INDEX(Hoja6!D$6:D$45,ROUND(RAND()*39,0)+1)} -> Alonso | F13: {=INDEX(Tabla9[id_direccion],ROUND(RAND()*215,0)+1)} -> P-DEL
C14: 90123456I | D14: {=INDEX(Hoja6!C$6:C$45,ROUND(RAND()*39,0)+1)} -> Paula | E14: {=INDEX(Hoja6!D$6:D$45,ROUND(RAND()*39,0)+1)} -> Álvarez | F14: {=INDEX(Tabla9[id_direccion],ROUND(RAND()*215,0)+1)} -> U-ADE
C15: 01234567J | D15: {=INDEX(Hoja6!C$6:C$45,ROUND(RAND()*39,0)+1)} -> Ana | E15: {=INDEX(Hoja6!D$6:D$45,ROUND(RAND()*39,0)+1)} -> García | F15: {=INDEX(Tabla9[id_direccion],ROUND(RAND()*215,0)+1)} -> M-LIN
C16: 12345678K | D16: {=INDEX(Hoja6!C$6:C$45,ROUND(RAND()*39,0)+1)} -> Marta | E16: {=INDEX(Hoja6!D$6:D$45,ROUND(RAND()*39,0)+1)} -> Gómez | F16: {=INDEX(Tabla9[id_direccion],ROUND(RAND()*215,0)+1)} -> S-ALL
C17: 23456789L | D17: {=INDEX(Hoja6!C$6:C$45,ROUND(RAND()*39,0)+1)} -> Sofía | E17: {=INDEX(Hoja6!D$6:D$45,ROUND(RAND()*39,0)+1)} -> López | F17: {=INDEX(Tabla9[id_direccion],ROUND(RAND()*215,0)+1)} -> L-ADE
... C109: 90123456Z | D109: {=INDEX(Hoja6!C$6:C$45,ROUND(RAND()*39,0)+1)} -> Jorge | E109: {=INDEX(Hoja6!D$6:D$45,ROUND(RAND()*39,0)+1)} -> Sánchez | F109: {=INDEX(Tabla9[id_direccion],ROUND(RAND()*215,0)+1)} -> A-DEL

Sheet dirección
B5: id_direccion | C5: provincia | D5: calle
B6: =CONCATENATE(UPPER(SUBSTITUTE(MID(C6,RANDBETWEEN(1,LEN(C6)),1)," ","")),"-",UPPER(SUBSTITUTE(MID(D6,RANDBETWEEN(1,LEN(D6)-2),3)," ",""))) -> A-DEL | C6: {=INDEX(Tabla5[codigo],ROUND(RAND()*45,0)+1)} -> PAL | D6: {=INDEX(Tabla8[id_calle],ROUND(RAND()*45,0)+1)} -> DELA
B7: =CONCATENATE(UPPER(SUBSTITUTE(MID(C7,RANDBETWEEN(1,LEN(C7)),1)," ","")),"-",UPPER(SUBSTITUTE(MID(D7,RANDBETWEEN(1,LEN(D7)-2),3)," ",""))) -> U-DEL | C7: {=INDEX(Tabla5[codigo],ROUND(RAND()*45,0)+1)} -> CUE | D7: {=INDEX(Tabla8[id_calle],ROUND(RAND()*45,0)+1)} -> DEL
B8: =CONCATENATE(UPPER(SUBSTITUTE(MID(C8,RANDBETWEEN(1,LEN(C8)),1)," ","")),"-",UPPER(SUBSTITUTE(MID(D8,RANDBETWEEN(1,LEN(D8)-2),3)," ",""))) -> E-UE1 | C8: {=INDEX(Tabla5[codigo],ROUND(RAND()*45,0)+1)} -> CEU | D8: {=INDEX(Tabla8[id_calle],ROUND(RAND()*45,0)+1)} -> UE18
B9: =CONCATENATE(UPPER(SUBSTITUTE(MID(C9,RANDBETWEEN(1,LEN(C9)),1)," ","")),"-",UPPER(SUBSTITUTE(MID(D9,RANDBETWEEN(1,LEN(D9)-2),3)," ",""))) -> G-LED | C9: {=INDEX(Tabla5[codigo],ROUND(RAND()*45,0)+1)} -> GUA | D9: {=INDEX(Tabla8[id_calle],ROUND(RAND()*45,0)+1)} -> LEDE
B10: =CONCATENATE(UPPER(SUBSTITUTE(MID(C10,RANDBETWEEN(1,LEN(C10)),1)," ","")),"-",UPPER(SUBSTITUTE(MID(D10,RANDBETWEEN(1,LEN(D10)-2),3)," ",""))) -> A-ADE | C10: {=INDEX(Tabla5[codigo],ROUND(RAND()*45,0)+1)} -> TAL | D10: {=INDEX(Tabla8[id_calle],ROUND(RAND()*45,0)+1)} -> ADE
B11: =CONCATENATE(UPPER(SUBSTITUTE(MID(C11,RANDBETWEEN(1,LEN(C11)),1)," ","")),"-",UPPER(SUBSTITUTE(MID(D11,RANDBETWEEN(1,LEN(D11)-2),3)," ",""))) -> L-NID | C11: {=INDEX(Tabla5[codigo],ROUND(RAND()*45,0)+1)} -> TAL | D11: {=INDEX(Tabla8[id_calle],ROUND(RAND()*45,0)+1)} -> NIDA
B12: =CONCATENATE(UPPER(SUBSTITUTE(MID(C12,RANDBETWEEN(1,LEN(C12)),1)," ","")),"-",UPPER(SUBSTITUTE(MID(D12,RANDBETWEEN(1,LEN(D12)-2),3)," ",""))) -> A-DEL | C12: {=INDEX(Tabla5[codigo],ROUND(RAND()*45,0)+1)} -> AVA | D12: {=INDEX(Tabla8[id_calle],ROUND(RAND()*45,0)+1)} -> DEL
B13: =CONCATENATE(UPPER(SUBSTITUTE(MID(C13,RANDBETWEEN(1,LEN(C13)),1)," ","")),"-",UPPER(SUBSTITUTE(MID(D13,RANDBETWEEN(1,LEN(D13)-2),3)," ",""))) -> A-LLE | C13: {=INDEX(Tabla5[codigo],ROUND(RAND()*45,0)+1)} -> BAL | D13: {=INDEX(Tabla8[id_calle],ROUND(RAND()*45,0)+1)} -> LLED
B14: =CONCATENATE(UPPER(SUBSTITUTE(MID(C14,RANDBETWEEN(1,LEN(C14)),1)," ","")),"-",UPPER(SUBSTITUTE(MID(D14,RANDBETWEEN(1,LEN(D14)-2),3)," ",""))) -> L-ELA | C14: {=INDEX(Tabla5[codigo],ROUND(RAND()*45,0)+1)} -> BAL | D14: {=INDEX(Tabla8[id_calle],ROUND(RAND()*45,0)+1)} -> ELA
B15: =CONCATENATE(UPPER(SUBSTITUTE(MID(C15,RANDBETWEEN(1,LEN(C15)),1)," ","")),"-",UPPER(SUBSTITUTE(MID(D15,RANDBETWEEN(1,LEN(D15)-2),3)," ",""))) -> M-AVE | C15: {=INDEX(Tabla5[codigo],ROUND(RAND()*45,0)+1)} -> MAL | D15: {=INDEX(Tabla8[id_calle],ROUND(RAND()*45,0)+1)} -> AVENI
B16: =CONCATENATE(UPPER(SUBSTITUTE(MID(C16,RANDBETWEEN(1,LEN(C16)),1)," ","")),"-",UPPER(SUBSTITUTE(MID(D16,RANDBETWEEN(1,LEN(D16)-2),3)," ",""))) -> R-ADE | C16: {=INDEX(Tabla5[codigo],ROUND(RAND()*45,0)+1)} -> ORU | D16: {=INDEX(Tabla8[id_calle],ROUND(RAND()*45,0)+1)} -> DADE
B17: =CONCATENATE(UPPER(SUBSTITUTE(MID(C17,RANDBETWEEN(1,LEN(C17)),1)," ","")),"-",UPPER(SUBSTITUTE(MID(D17,RANDBETWEEN(1,LEN(D17)-2),3)," ",""))) -> I-LAA | C17: {=INDEX(Tabla5[codigo],ROUND(RAND()*45,0)+1)} -> GIP | D17: {=INDEX(Tabla8[id_calle],ROUND(RAND()*45,0)+1)} -> LAA
... B222: =CONCATENATE(UPPER(SUBSTITUTE(MID(C222,RANDBETWEEN(1,LEN(C222)),1)," ","")),"-",UPPER(SUBSTITUTE(MID(D222,RANDBETWEEN(1,LEN(D222)-2),3)," ",""))) -> O-ENT | C222: {=INDEX(Tabla5[codigo],ROUND(RAND()*45,0)+1)} -> ORE | D222: {=INDEX(Tabla8[id_calle],ROUND(RAND()*45,0)+1)} -> ENTO

Sheet Calles
B4: id_calle | C4: nombre
B5: =UPPER(SUBSTITUTE(MID(C5,RANDBETWEEN(1,LEN(C5)-4),5)," ","")) -> ANJU | C5: Calle San Juan 5
B6: =UPPER(SUBSTITUTE(MID(C6,RANDBETWEEN(1,LEN(C6)-4),5)," ","")) -> AVENI | C6: Avenida del Sol 12
B7: =UPPER(SUBSTITUTE(MID(C7,RANDBETWEEN(1,LEN(C7)-4),5)," ","")) -> ELA | C7: Calle de la Luna 25
B8: =UPPER(SUBSTITUTE(MID(C8,RANDBETWEEN(1,LEN(C8)-4),5)," ","")) -> LLED | C8: Calle del Mar 8
B9: =UPPER(SUBSTITUTE(MID(C9,RANDBETWEEN(1,LEN(C9)-4),5)," ","")) -> CALLE | C9: Calle de la Primavera 3
B10: =UPPER(SUBSTITUTE(MID(C10,RANDBETWEEN(1,LEN(C10)-4),5)," ","")) -> OÑO1 | C10: Calle del Otoño 14
B11: =UPPER(SUBSTITUTE(MID(C11,RANDBETWEEN(1,LEN(C11)-4),5)," ","")) -> AVENI | C11: Avenida del Viento 9
B12: =UPPER(SUBSTITUTE(MID(C12,RANDBETWEEN(1,LEN(C12)-4),5)," ","")) -> AÑA2 | C12: Calle de la Montaña 21
B13: =UPPER(SUBSTITUTE(MID(C13,RANDBETWEEN(1,LEN(C13)-4),5)," ","")) -> AVENI | C13: Avenida del Río 4
B14: =UPPER(SUBSTITUTE(MID(C14,RANDBETWEEN(1,LEN(C14)-4),5)," ","")) -> LLED | C14: Calle del Bosque 17
B15: =UPPER(SUBSTITUTE(MID(C15,RANDBETWEEN(1,LEN(C15)-4),5)," ","")) -> PLAY | C15: Calle de la Playa 6
B16: =UPPER(SUBSTITUTE(MID(C16,RANDBETWEEN(1,LEN(C16)-4),5)," ","")) -> DADE | C16: Avenida del Campo 29
... B96: =UPPER(SUBSTITUTE(MID(C96,RANDBETWEEN(1,LEN(C96)-4),5)," ","")) -> TAD1 | C96: Avenida de la Libertad 1

Sheet Provincias
B4: codigo | C4: nombre
B5: ACO | C5: A Coruña
B6: ALA | C6: Álava
B7: ALB | C7: Albacete
B8: ALI | C8: Alicante
B9: ALM | C9: Almería
B10: AVA | C10: Ávila
B11: BAD | C11: Badajoz
B12: BAL | C12: Baleares
B13: BAR | C13: Barcelona
B14: BUR | C14: Burgos
B15: CAC | C15: Cáceres
... B54: ZAR | C54: Zaragoza

Sheet Hoja6
C5: Columna1 | D5: Columna1
C6: Ana | D6: García | F6: =CONCATENATE(INDEX(nombres,ROUND(RAND()*39,0)+1)," ",INDEX($D$6:$D$45,ROUND(RAND()*39,0)+1)) -> Carmen Gómez | H6: James | I6: Smith | J6: =CONCATENATE(INDEX($H$6:$H$15,ROUND(RAND()*9,0)+1)," ",INDEX($I$6:$I$15,ROUND(RAND()*9,0)+1)) -> James Brown | L6: Película
C7: Carlos | D7: López | F7: =CONCATENATE(INDEX(nombres,ROUND(RAND()*39,0)+1)," ",INDEX($D$6:$D$45,ROUND(RAND()*39,0)+1)) -> Miguel Martínez | H7: Emily | I7: Johnson | J7: =CONCATENATE(INDEX($H$6:$H$15,ROUND(RAND()*9,0)+1)," ",INDEX($I$6:$I$15,ROUND(RAND()*9,0)+1)) -> Charlotte Anderson | L7: Camisa
C8: Laura | D8: Martínez | F8: =CONCATENATE(INDEX(nombres,ROUND(RAND()*39,0)+1)," ",INDEX($D$6:$D$45,ROUND(RAND()*39,0)+1)) -> Raquel Torres | H8: William | I8: Brown | J8: =CONCATENATE(INDEX($H$6:$H$15,ROUND(RAND()*9,0)+1)," ",INDEX($I$6:$I$15,ROUND(RAND()*9,0)+1)) -> Olivia Johnson | L8: Botella de agua
C9: Juan | D9: Rodríguez | F9: =CONCATENATE(INDEX(nombres,ROUND(RAND()*39,0)+1)," ",INDEX($D$6:$D$45,ROUND(RAND()*39,0)+1)) -> Sofía Díaz | H9: Charlotte | I9: Davis | J9: =CONCATENATE(INDEX($H$6:$H$15,ROUND(RAND()*9,0)+1)," ",INDEX($I$6:$I$15,ROUND(RAND()*9,0)+1)) -> William Jackson | L9: Reloj de pulsera
C10: Isabel | D10: Sánchez | F10: =CONCATENATE(INDEX(nombres,ROUND(RAND()*39,0)+1)," ",INDEX($D$6:$D$45,ROUND(RAND()*39,0)+1)) -> Francisco Martínez | H10: Benjamin | I10: Miller | J10: =CONCATENATE(INDEX($H$6:$H$15,ROUND(RAND()*9,0)+1)," ",INDEX($I$6:$I$15,ROUND(RAND()*9,0)+1)) -> Emma Davis | L10: Lápiz
C11: Pedro | D11: Pérez | F11: =CONCATENATE(INDEX(nombres,ROUND(RAND()*39,0)+1)," ",INDEX($D$6:$D$45,ROUND(RAND()*39,0)+1)) -> Francisco Rodríguez | H11: Olivia | I11: Wilson | J11: =CONCATENATE(INDEX($H$6:$H$15,ROUND(RAND()*9,0)+1)," ",INDEX($I$6:$I$15,ROUND(RAND()*9,0)+1)) -> Ethan Smith | L11: Bolsa de papel
C12: Sofía | D12: Gómez | F12: =CONCATENATE(INDEX(nombres,ROUND(RAND()*39,0)+1)," ",INDEX($D$6:$D$45,ROUND(RAND()*39,0)+1)) -> Laura Rodríguez | H12: Ethan | I12: Moore | J12: =CONCATENATE(INDEX($H$6:$H$15,ROUND(RAND()*9,0)+1)," ",INDEX($I$6:$I$15,ROUND(RAND()*9,0)+1)) -> Charlotte Brown | L12: Mochila
C13: Sergio | D13: Fernández | F13: =CONCATENATE(INDEX(nombres,ROUND(RAND()*39,0)+1)," ",INDEX($D$6:$D$45,ROUND(RAND()*39,0)+1)) -> Isabel Pérez | H13: Emma | I13: Taylor | J13: =CONCATENATE(INDEX($H$6:$H$15,ROUND(RAND()*9,0)+1)," ",INDEX($I$6:$I$15,ROUND(RAND()*9,0)+1)) -> Ethan Johnson | L13: Gafas de sol
C14: Marta | D14: González | F14: =CONCATENATE(INDEX(nombres,ROUND(RAND()*39,0)+1)," ",INDEX($D$6:$D$45,ROUND(RAND()*39,0)+1)) -> Juan Gómez | H14: Alexander | I14: Anderson | J14: =CONCATENATE(INDEX($H$6:$H$15,ROUND(RAND()*9,0)+1)," ",INDEX($I$6:$I$15,ROUND(RAND()*9,0)+1)) -> Ethan Anderson | L14: Cepillo de dientes
C15: Alejandro | D15: Torres | F15: =CONCATENATE(INDEX(nombres,ROUND(RAND()*39,0)+1)," ",INDEX($D$6:$D$45,ROUND(RAND()*39,0)+1)) -> Carmen Gómez | H15: Sophia | I15: Jackson | J15: =CONCATENATE(INDEX($H$6:$H$15,ROUND(RAND()*9,0)+1)," ",INDEX($I$6:$I$15,ROUND(RAND()*9,0)+1)) -> Olivia Miller | L15: Perfume
C16: Paula | D16: Ruiz | F16: =CONCATENATE(INDEX(nombres,ROUND(RAND()*39,0)+1)," ",INDEX($D$6:$D$45,ROUND(RAND()*39,0)+1)) -> Miguel Rodríguez | J16: =CONCATENATE(INDEX($H$6:$H$15,ROUND(RAND()*9,0)+1)," ",INDEX($I$6:$I$15,ROUND(RAND()*9,0)+1)) -> Emily Johnson | L16: Vino
C17: Álvaro | D17: Hernández | F17: =CONCATENATE(INDEX(nombres,ROUND(RAND()*39,0)+1)," ",INDEX($D$6:$D$45,ROUND(RAND()*39,0)+1)) -> Ana Sánchez | J17: =CONCATENATE(INDEX($H$6:$H$15,ROUND(RAND()*9,0)+1)," ",INDEX($I$6:$I$15,ROUND(RAND()*9,0)+1)) -> Ethan Johnson | L17: Pintura
C18: Lucía | D18: Díaz | F18: =CONCATENATE(INDEX(nombres,ROUND(RAND()*39,0)+1)," ",INDEX($D$6:$D$45,ROUND(RAND()*39,0)+1)) -> Jorge Muñoz | J18: =CONCATENATE(INDEX($H$6:$H$15,ROUND(RAND()*9,0)+1)," ",INDEX($I$6:$I$15,ROUND(RAND()*9,0)+1)) -> Sophia Miller | L18: Zapatos
C19: Jorge | D19: Moreno | F19: =CONCATENATE(INDEX(nombres,ROUND(RAND()*39,0)+1)," ",INDEX($D$6:$D$45,ROUND(RAND()*39,0)+1)) -> Raquel López | J19: =CONCATENATE(INDEX($H$6:$H$15,ROUND(RAND()*9,0)+1)," ",INDEX($I$6:$I$15,ROUND(RAND()*9,0)+1)) -> Alexander Johnson | L19: Silla
C20: Carmen | D20: Muñoz | F20: =CONCATENATE(INDEX(nombres,ROUND(RAND()*39,0)+1)," ",INDEX($D$6:$D$45,ROUND(RAND()*39,0)+1)) -> Carmen Díaz | J20: =CONCATENATE(INDEX($H$6:$H$15,ROUND(RAND()*9,0)+1)," ",INDEX($I$6:$I$15,ROUND(RAND()*9,0)+1)) -> Olivia Anderson | L20: Bolígrafo
C21: Miguel | D21: Álvarez | F21: =CONCATENATE(INDEX(nombres,ROUND(RAND()*39,0)+1)," ",INDEX($D$6:$D$45,ROUND(RAND()*39,0)+1)) -> Paula Muñoz | J21: =CONCATENATE(INDEX($H$6:$H$15,ROUND(RAND()*9,0)+1)," ",INDEX($I$6:$I$15,ROUND(RAND()*9,0)+1)) -> Charlotte Johnson | L21: Maleta
C22: Natalia | D22: Romero | F22: =CONCATENATE(INDEX(nombres,ROUND(RAND()*39,0)+1)," ",INDEX($D$6:$D$45,ROUND(RAND()*39,0)+1)) -> Ana Sánchez | J22: =CONCATENATE(INDEX($H$6:$H$15,ROUND(RAND()*9,0)+1)," ",INDEX($I$6:$I$15,ROUND(RAND()*9,0)+1)) -> Ethan Brown | L22: Guitarra
C23: David | D23: Jiménez | F23: =CONCATENATE(INDEX(nombres,ROUND(RAND()*39,0)+1)," ",INDEX($D$6:$D$45,ROUND(RAND()*39,0)+1)) -> Francisco López | J23: =CONCATENATE(INDEX($H$6:$H$15,ROUND(RAND()*9,0)+1)," ",INDEX($I$6:$I$15,ROUND(RAND()*9,0)+1)) -> Emma Anderson | L23: Jabón de manos
C24: Raquel | D24: Alonso | F24: =CONCATENATE(INDEX(nombres,ROUND(RAND()*39,0)+1)," ",INDEX($D$6:$D$45,ROUND(RAND()*39,0)+1)) -> Ana Ruiz | J24: =CONCATENATE(INDEX($H$6:$H$15,ROUND(RAND()*9,0)+1)," ",INDEX($I$6:$I$15,ROUND(RAND()*9,0)+1)) -> James Brown | L24: Pelota de fútbol
C25: Francisco | D25: Navarro | F25: =CONCATENATE(INDEX(nombres,ROUND(RAND()*39,0)+1)," ",INDEX($D$6:$D$45,ROUND(RAND()*39,0)+1)) -> Juan Ruiz | J25: =CONCATENATE(INDEX($H$6:$H$15,ROUND(RAND()*9,0)+1)," ",INDEX($I$6:$I$15,ROUND(RAND()*9,0)+1)) -> Emma Taylor | L25: Auriculares
C26: Ana | D26: García | F26: =CONCATENATE(INDEX(nombres,ROUND(RAND()*39,0)+1)," ",INDEX($D$6:$D$45,ROUND(RAND()*39,0)+1)) -> Paula Sánchez | J26: =CONCATENATE(INDEX($H$6:$H$15,ROUND(RAND()*9,0)+1)," ",INDEX($I$6:$I$15,ROUND(RAND()*9,0)+1)) -> Olivia Brown | L26: Planta
C27: Carlos | D27: López | F27: =CONCATENATE(INDEX(nombres,ROUND(RAND()*39,0)+1)," ",INDEX($D$6:$D$45,ROUND(RAND()*39,0)+1)) -> Laura Muñoz | J27: =CONCATENATE(INDEX($H$6:$H$15,ROUND(RAND()*9,0)+1)," ",INDEX($I$6:$I$15,ROUND(RAND()*9,0)+1)) -> Alexander Jackson | L27: Lámpara
C28: Laura | D28: Martínez | J28: =CONCATENATE(INDEX($H$6:$H$15,ROUND(RAND()*9,0)+1)," ",INDEX($I$6:$I$15,ROUND(RAND()*9,0)+1)) -> Alexander Moore | L28: Caja de herramientas
C29: Juan | D29: Rodríguez | J29: =CONCATENATE(INDEX($H$6:$H$15,ROUND(RAND()*9,0)+1)," ",INDEX($I$6:$I$15,ROUND(RAND()*9,0)+1)) -> Benjamin Wilson | L29: Calcetines
C30: Isabel | D30: Sánchez | J30: =CONCATENATE(INDEX($H$6:$H$15,ROUND(RAND()*9,0)+1)," ",INDEX($I$6:$I$15,ROUND(RAND()*9,0)+1)) -> Emma Davis | L30: Crema hidratante
C31: Pedro | D31: Pérez | J31: =CONCATENATE(INDEX($H$6:$H$15,ROUND(RAND()*9,0)+1)," ",INDEX($I$6:$I$15,ROUND(RAND()*9,0)+1)) -> Emma Wilson | L31: Taza
C32: Sofía | D32: Gómez | J32: =CONCATENATE(INDEX($H$6:$H$15,ROUND(RAND()*9,0)+1)," ",INDEX($I$6:$I$15,ROUND(RAND()*9,0)+1)) -> Emma Miller | L32: Papel higiénico
C33: Sergio | D33: Fernández | J33: =CONCATENATE(INDEX($H$6:$H$15,ROUND(RAND()*9,0)+1)," ",INDEX($I$6:$I$15,ROUND(RAND()*9,0)+1)) -> Ethan Miller | L33: Cámara
C34: Marta | D34: González | J34: =CONCATENATE(INDEX($H$6:$H$15,ROUND(RAND()*9,0)+1)," ",INDEX($I$6:$I$15,ROUND(RAND()*9,0)+1)) -> Benjamin Moore | L34: Toalla
C35: Alejandro | D35: Torres | J35: =CONCATENATE(INDEX($H$6:$H$15,ROUND(RAND()*9,0)+1)," ",INDEX($I$6:$I$15,ROUND(RAND()*9,0)+1)) -> Sophia Anderson | L35: Pantalones
C36: Paula | D36: Ruiz | J36: =CONCATENATE(INDEX($H$6:$H$15,ROUND(RAND()*9,0)+1)," ",INDEX($I$6:$I$15,ROUND(RAND()*9,0)+1)) -> Charlotte Davis | L36: Paquete de galletas
C37: Álvaro | D37: Hernández | J37: =CONCATENATE(INDEX($H$6:$H$15,ROUND(RAND()*9,0)+1)," ",INDEX($I$6:$I$15,ROUND(RAND()*9,0)+1)) -> Olivia Smith | L37: Altavoz
C38: Lucía | D38: Díaz | J38: =CONCATENATE(INDEX($H$6:$H$15,ROUND(RAND()*9,0)+1)," ",INDEX($I$6:$I$15,ROUND(RAND()*9,0)+1)) -> Charlotte Davis | L38: Teclado
C39: Jorge | D39: Moreno | J39: =CONCATENATE(INDEX($H$6:$H$15,ROUND(RAND()*9,0)+1)," ",INDEX($I$6:$I$15,ROUND(RAND()*9,0)+1)) -> Alexander Brown | L39: Botas
... C45: Francisco | D45: Navarro | J45: =CONCATENATE(INDEX($H$6:$H$15,ROUND(RAND()*9,0)+1)," ",INDEX($I$6:$I$15,ROUND(RAND()*9,0)+1)) -> Ethan Miller | L45: Videojuego
J46: =CONCATENATE(INDEX($H$6:$H$15,ROUND(RAND()*9,0)+1)," ",INDEX($I$6:$I$15,ROUND(RAND()*9,0)+1)) -> Emily Brown | L46: Agua tónica
J47: =CONCATENATE(INDEX($H$6:$H$15,ROUND(RAND()*9,0)+1)," ",INDEX($I$6:$I$15,ROUND(RAND()*9,0)+1)) -> Emma Anderson | L47: Patineta
J48: =CONCATENATE(INDEX($H$6:$H$15,ROUND(RAND()*9,0)+1)," ",INDEX($I$6:$I$15,ROUND(RAND()*9,0)+1)) -> Emily Wilson | L48: Monitor
L49: Carcasa para móvil
...
